Workbook

Sheet #1 NFLX share prices
A1: Date | B1: Close/Last | C1: Volume | D1: Open | E1: High | F1: Low
A2: 46118 | B2: 98.93 | C2: 37029330 | D2: 100.96 | E2: 102.685 | F2: 97.97
A3: 46114 | B3: 98.66 | C3: 37068020 | D3: 95.27 | E3: 98.71 | F3: 95.17
A4: 46113 | B4: 95.55 | C4: 30439310 | D4: 96.47 | E4: 97.2 | F4: 94.264
A5: 46112 | B5: 96.15 | C5: 54269960 | D5: 93.03 | E5: 96.26 | F5: 93.03
A6: 46111 | B6: 92.97 | C6: 32375140 | D6: 92.75 | E6: 94.49 | F6: 92.22
A7: 46108 | B7: 93.43 | C7: 44590670 | D7: 94.57 | E7: 95.5799 | F7: 92.74
A8: 46107 | B8: 93.32 | C8: 59522030 | D8: 91.52 | E8: 95.86 | F8: 91.01
A9: 46106 | B9: 92.28 | C9: 29545630 | D9: 91.71 | E9: 92.52 | F9: 91.235
A10: 46105 | B10: 90.92 | C10: 28938030 | D10: 92.79 | E10: 93.7398 | F10: 90.815
A11: 46104 | B11: 93.38 | C11: 34315870 | D11: 92.04 | E11: 93.98 | F11: 91.86
A12: 46101 | B12: 91.82 | C12: 61678010 | D12: 91.31 | E12: 91.88 | F12: 90.69
A13: 46100 | B13: 91.74 | C13: 40169250 | D13: 94.31 | E13: 95.75 | F13: 90.775
... A2514: 42467 | B2514: 10.445 | C2514: 107672800 | D2514: 10.431 | E2514: 10.6435 | F2514: 10.36

Sheet #1 LMT share prices
A1: Date | B1: Close/Last | C1: Volume | D1: Open | E1: High | F1: Low
A2: 46118 | B2: 637.9 | C2: 1128782 | D2: 623.11 | E2: 637.92 | F2: 621.365
A3: 46114 | B3: 622.79 | C3: 1116763 | D3: 616.7 | E3: 626.51 | F3: 616.01
A4: 46113 | B4: 617.64 | C4: 1118050 | D4: 608.82 | E4: 619.1 | F4: 606.11
A5: 46112 | B5: 604.39 | C5: 1327800 | D5: 604.5 | E5: 610 | F5: 598.7
A6: 46111 | B6: 598.57 | C6: 1849318 | D6: 621.03 | E6: 623.32 | F6: 593.88
A7: 46108 | B7: 615.84 | C7: 1061125 | D7: 625.7 | E7: 631.445 | F7: 613.6551
A8: 46107 | B8: 627.33 | C8: 1262434 | D8: 619.8 | E8: 632.92 | F8: 619.8
A9: 46106 | B9: 624.2 | C9: 1190275 | D9: 612.5 | E9: 626.93 | F9: 612.42
A10: 46105 | B10: 610.17 | C10: 1078188 | D10: 612.95 | E10: 615.3 | F10: 605.0001
A11: 46104 | B11: 616.25 | C11: 1386641 | D11: 629.07 | E11: 629.6579 | F11: 610.63
A12: 46101 | B12: 627.43 | C12: 6511253 | D12: 635.86 | E12: 638.5099 | F12: 622.37
A13: 46100 | B13: 637.51 | C13: 1540841 | D13: 639.06 | E13: 640 | F13: 623.75
... A2514: 42467 | B2514: 226.48 | C2514: 1063202 | D2514: 226 | E2514: 227.41 | F2514: 225.64

Sheet #2-3 NFLX
A1: NAME: | C1: NETFLIX INC
A2: TICKER SYMBOL: | C2: NFLX
A3: PRIMARY SIC CODE: | C3: 7841
A4: STOCK EXCHANGE: | C4: 14 | D4: NASDAQ-NMS Stock Market
A5: CUSIP: | C5: 64110L
A8: STATEMENT OF FINANCIAL POSITION
A9: Fiscal Year: | C9: 2021 | D9: 2022 | E9: 2023 | F9: 2024 | G9: 2025 | J9: 2021 | K9: 2022 | L9: 2023 | M9: 2024 | N9: 2025 | P9: Peer valuation
A10: (FYR Ending): | C10: (31DEC2021 ) | D10: (31DEC2022 ) | E10: (31DEC2023 ) | F10: (31DEC2024 ) | G10: (31DEC2025 ) | I10: Valuation | P10: Latest ratios | Q10: NFLX | R10: DIS | S10: Notes
A11: ASSETS | I11: Share Price (end of year) | J11: 60.244 | K11: 29.488 | L11: 48.688 | M11: 89.132 | N11: 93.76 | P11: Price/book | Q11: =N20 -> 15.302391 | R11: 1.62 | S11: DIS - much lower due to declining profitability with share price dropping by half recently
A12: Cash & Equivalents | C12: 6027.804 | D12: 6058.452 | E12: 7139.352 | F12: 9586.211 | G12: 9067.728 | I12: Earnings | J12: =C89 -> 5116.228 | K12: =D89 -> 4491.924 | L12: =E89 -> 5407.99 | M12: =F89 -> 8711.631 | N12: =G89 -> 10981.201 | P12: P/E | Q12: =N14 -> 37.088894 | R12: 17.1 | S12: NFLX much higher do to higher EPS growth expectations
A13: Receivables - Total (Net) | C13: 804.32 | D13: 988.898 | E13: 1287.054 | F13: 1988.304 | G13: 2583.476 | I13: EPS | J13: =J12/J16 -> 1.1235271 | K13: =K12/K16 -> 0.99535199 | L13: =L12/L16 -> 1.2031177 | M13: =M12/M16 -> 1.9832471 | N13: =N12/N16 -> 2.5279805
A14: Inventories - Total | C14: 0 | D14: 0 | E14: 0 | F14: 0 | G14: 0 | I14: P/E | J14: =J11/J13 -> 53.620423 | K14: =K11/K13 -> 29.625701 | L14: =L11/L13 -> 40.468194 | M14: =M11/M13 -> 44.942458 | N14: =N11/N13 -> 37.088894
A15: Prepaid Expenses | C15: 323.818 | D15: 392.735 | E15: 408.936 | F15: 431.924 | G15: 498.054
A16: Current Assets - Other | C16: 913.883 | D16: 1826.388 | E16: 1082.791 | F16: 1093.94 | G16: 870.933 | I16: # shares | J16: =C105*10 -> 4553.72 | K16: =D105*10 -> 4512.9 | L16: =E105*10 -> 4494.98 | M16: =F105*10 -> 4392.61 | N16: =G105 -> 4343.863
I17: Market value | J17: =J16*J11 -> 274334.31 | K17: =K16*K11 -> 133076.4 | L17: =L16*L11 -> 218851.59 | M17: =M16*M11 -> 391522.11 | N17: =N16*N11 -> 407280.59
A18: Current Assets - Total | C18: 8069.825 | D18: 9266.473 | E18: 9918.133 | F18: 13100.379 | G18: 13020.191
I19: Book value | J19: =C60 -> 15849.248 | K19: =D60 -> 20777.401 | L19: =E60 -> 20588.313 | M19: =F60 -> 24743.567 | N19: =G60 -> 26615.488
A20: Plant, Property & Equip (Gross) | C20: 4386.332 | D20: 4379.12 | E20: 4423.386 | F20: 4613.603 | G20: 5308.402 | I20: Market/Book | J20: =J17/J19 -> 17.308979 | K20: =K17/K19 -> 6.4048624 | L20: =L17/L19 -> 10.629894 | M20: =M17/M19 -> 15.823188 | N20: =N17/N19 -> 15.302391
A21: Accumulated Depreciation | C21: 616.306 | D21: 753.741 | E21: 855.043 | F21: 917.537 | G21: 1096.891
I22: LT Debt | J22: =C43 -> 17101.558 | K22: =D43 -> 16575.579 | L22: =E43 -> 16190.218 | M22: =F43 -> 15782.039 | N22: =G43 -> 15516.497
A23: Plant, Property & Equip (Net) | C23: 3770.026 | D23: 3625.379 | E23: 3568.343 | F23: 3696.066 | G23: 4211.511 | I23: ST Debt | J23: =C38 -> 1015.012 | K23: =D38 -> 355.985 | L23: =E38 -> 783.156 | M23: =F38 -> 2212.935 | N23: =G38 -> 1459.34
I24: Total Debt | J24: =J22+J23 -> 18116.57 | K24: =K22+K23 -> 16931.564 | L24: =L22+L23 -> 16973.374 | M24: =M22+M23 -> 17994.974 | N24: =N22+N23 -> 16975.837
A25: Investments at Equity | C25: 0 | D25: 0 | E25: 0 | F25: 0 | G25: 0
A26: Investments and Advances - Other | C26: 0.146 | D26: 0.122 | E26: 0.055 | F26: 0.058 | G26: 0.06 | I26: Cash | J26: =C12 -> 6027.804 | K26: =D12 -> 6058.452 | L26: =E12 -> 7139.352 | M26: =F12 -> 9586.211 | N26: =G12 -> 9067.728
A27: Intangibles | C27: 0 | D27: 0 | E27: 0 | F27: 0 | G27: 0
A28: Deferred Charges | C28: 0 | D28: 0 | E28: 0 | F28: 0 | G28: 0 | I28: Enterprise value | J28: =J17+J24-J26 -> 286423.07 | K28: =K17+K24-K26 -> 143949.51 | L28: =L17+L24-L26 -> 228685.61 | M28: =M17+M24-M26 -> 399930.88 | N28: =N17+N24-N26 -> 415188.7
A29: Assets - Other | C29: 32744.666 | D29: 35702.794 | E29: 35245.461 | F29: 36833.871 | G29: 38365.231
I30: EBITDA | J30: =C74 -> 6402.921 | K30: =D74 -> 5969.513 | L30: =E74 -> 7310.95 | M30: =F74 -> 10746.528 | N30: =G74 -> 14278.992
A31: TOTAL ASSETS | C31: 44584.663 | D31: 48594.768 | E31: 48731.992 | F31: 53630.374 | G31: 55596.993
I32: Enterprise value/EBITDA | J32: =J28/J30 -> 44.733189 | K32: =K28/K30 -> 24.114112 | L32: =L28/L30 -> 31.279876 | M32: =M28/M30 -> 37.214892 | N32: =N28/N30 -> 29.076892
A33: LIABILITIES
A34: Accounts Payable | C34: 5130.45 | D34: 5151.663 | E34: 5213.882 | F34: 5293.59 | G34: 4985.466 | I34: Profitability
A35: Notes Payable | C35: 0 | D35: 0 | E35: 0 | F35: 0 | G35: 0 | I35: Operating Margin (EBIT/Sales) | J35: =C77/C68 -> 0.20858447 | K35: =D77/D68 -> 0.17816647 | L35: =E77/E68 -> 0.20620768 | M35: =F77/F68 -> 0.26711169 | N35: =G77/G68 -> 0.30864688
A36: Accrued Expenses
A37: Taxes Payable | C37: 0 | D37: 0 | E37: 0 | F37: 0 | G37: 0 | I37: Net profit margin | J37: =C89/C68 -> 0.17227607 | K37: =D89/D68 -> 0.14207958 | L37: =E89/E68 -> 0.16036362 | M37: =F89/F68 -> 0.22336962 | N37: =G89/G68 -> 0.24303814
A38: Debt (Long-Term) Due In One Year | C38: 1015.012 | D38: 355.985 | E38: 783.156 | F38: 2212.935 | G38: 1459.34
A39: Other Current Liabilities | C39: 2343.504 | D39: 2423.326 | E39: 2863.617 | F39: 3248.875 | G39: 4536.124 | I39: Equity | J39: =C60 -> 15849.248 | K39: =D60 -> 20777.401 | L39: =E60 -> 20588.313 | M39: =F60 -> 24743.567 | N39: =G60 -> 26615.488
I40: Average Equity | K40: =(J39+K39)/2 -> 18313.325 | L40: =(K39+L39)/2 -> 20682.857 | M40: =(L39+M39)/2 -> 22665.94 | N40: =(M39+N39)/2 -> 25679.528
A41: Total Current Liabilities | C41: 8488.966 | D41: 7930.974 | E41: 8860.655 | F41: 10755.4 | G41: 10980.93
I42: ROE (based on prior ending) | K42: =D89/J39 -> 0.28341559 | L42: =E89/K39 -> 0.26028231 | M42: =F89/L39 -> 0.42313477 | N42: =G89/M39 -> 0.44380024
...

Sheet #2-3 LMT
A1: NAME: | C1: LOCKHEED MARTIN CORP
A2: TICKER SYMBOL: | C2: LMT
A3: PRIMARY SIC CODE: | C3: 3760
A4: STOCK EXCHANGE: | C4: 11 | D4: New York Stock Exchange
A5: CUSIP: | C5: 539830
A8: STATEMENT OF FINANCIAL POSITION
A9: Fiscal Year: | C9: 2021 | D9: 2022 | E9: 2023 | F9: 2024 | G9: 2025 | J9: 2021 | K9: 2022 | L9: 2023 | M9: 2024 | N9: 2025 | P9: Peer valuation
A10: (FYR Ending): | C10: (31DEC2021 ) | D10: (31DEC2022 ) | E10: (31DEC2023 ) | F10: (31DEC2024 ) | G10: (31DEC2025 ) | I10: Valuation | P10: Latest ratios | Q10: LMT | R10: BA | S10: Notes
A11: ASSETS | I11: Share Price (end of year) | J11: 355.41 | K11: 486.49 | L11: 453.24 | M11: 485.94 | N11: 483.67 | P11: Price/book | Q11: =N20 -> 16.479755 | R11: 182.88 | S11: BA earnings collapsed resulting in odd P/E ratio
A12: Cash & Equivalents | C12: 3604 | D12: 2547 | E12: 1442 | F12: 2483 | G12: 4121 | I12: Earnings | J12: =C89 -> 6315 | K12: =D89 -> 5732 | L12: =E89 -> 6920 | M12: =F89 -> 5336 | N12: =G89 -> 5017 | P12: P/E | Q12: =N14 -> 22.077024 | R12: 26.54 | S12: similar
A13: Receivables - Total (Net) | C13: 12542 | D13: 14823 | E13: 15315 | F13: 15308 | G13: 16902 | I13: EPS | J13: =J12/C106 -> 23.302583 | K13: =K12/D106 -> 22.566929 | L13: =L12/E106 -> 28.833333 | M13: =M12/F106 -> 22.803419 | N13: =N12/G106 -> 21.908297
A14: Inventories - Total | C14: 2981 | D14: 3088 | E14: 3132 | F14: 3474 | G14: 3524 | I14: P/E | J14: =J11/J13 -> 15.251957 | K14: =K11/K13 -> 21.557652 | L14: =L11/L13 -> 15.719306 | M14: =M11/M13 -> 21.309963 | N14: =N11/N13 -> 22.077024
A15: Prepaid Expenses | C15: 0 | D15: 0 | E15: 0 | F15: 0 | G15: 0
A16: Current Assets - Other | C16: 688 | D16: 533 | E16: 632 | F16: 584 | G16: 815 | I16: # shares | J16: =C106 -> 271 | K16: =D106 -> 254 | L16: =E106 -> 240 | M16: =F106 -> 234 | N16: =G106 -> 229
I17: Market value | J17: =J16*J11 -> 96316.11 | K17: =K16*K11 -> 123568.46 | L17: =L16*L11 -> 108777.6 | M17: =M16*M11 -> 113709.96 | N17: =N16*N11 -> 110760.43
A18: Current Assets - Total | C18: 19815 | D18: 20991 | E18: 20521 | F18: 21849 | G18: 25362
I19: Book value | J19: =C60 -> 10959 | K19: =D60 -> 9266 | L19: =E60 -> 6835 | M19: =F60 -> 6333 | N19: =G60 -> 6721
A20: Plant, Property & Equip (Gross) | C20: 20400 | D20: 21238 | E20: 22282 | F20: 23219 | G20: 24079 | I20: Market/Book | J20: =J17/J19 -> 8.7887681 | K20: =K17/K19 -> 13.335685 | L20: =L17/L19 -> 15.914792 | M20: =M17/M19 -> 17.955149 | N20: =N17/N19 -> 16.479755
A21: Accumulated Depreciation | C21: 11503 | D21: 12163 | E21: 12812 | F21: 13493 | G21: 14228
I22: LT Debt | J22: =C43 -> 12770 | K22: =D43 -> 16345 | L22: =E43 -> 18153 | M22: =F43 -> 20460 | N22: =G43 -> 21357
A23: Plant, Property & Equip (Net) | C23: 8897 | D23: 9075 | E23: 9470 | F23: 9726 | G23: 9851 | I23: ST Debt | J23: =C38 -> 332 | K23: =D38 -> 419 | L23: =E38 -> 483 | M23: =F38 -> 958 | N23: =G38 -> 1414
I24: Total Debt | J24: =J22+J23 -> 13102 | K24: =K22+K23 -> 16764 | L24: =L22+L23 -> 18636 | M24: =M22+M23 -> 21418 | N24: =N22+N23 -> 22771
A25: Investments at Equity | C25: 689 | D25: 685 | E25: 701 | F25: 654 | G25: 653
A26: Investments and Advances - Other | I26: Cash | J26: =C12 -> 3604 | K26: =D12 -> 2547 | L26: =E12 -> 1442 | M26: =F12 -> 2483 | N26: =G12 -> 4121
A27: Intangibles | C27: 14296 | D27: 14158 | E27: 14411 | F27: 14982 | G27: 15618
A28: Deferred Charges | E28: 0 | F28: 0 | G28: 0 | I28: Enterprise value | J28: =J17+J24-J26 -> 105814.11 | K28: =K17+K24-K26 -> 137785.46 | L28: =L17+L24-L26 -> 125971.6 | M28: =M17+M24-M26 -> 132644.96 | N28: =N17+N24-N26 -> 129410.43
A29: Assets - Other | C29: 7176 | D29: 7971 | E29: 7353 | F29: 8406 | G29: 8356
I30: EBITDA | J30: =C74 -> 10461 | K30: =D74 -> 9791 | L30: =E74 -> 10001 | M30: =F74 -> 8576 | N30: =G74 -> 9372
A31: TOTAL ASSETS | C31: 50873 | D31: 52880 | E31: 52456 | F31: 55617 | G31: 59840
I32: Enterprise value/EBITDA | J32: =J28/J30 -> 10.115105 | K32: =K28/K30 -> 14.072665 | L32: =L28/L30 -> 12.5959 | M32: =M28/M30 -> 15.466996 | N32: =N28/N30 -> 13.808198
A33: LIABILITIES
A34: Accounts Payable | C34: 780 | D34: 2117 | E34: 2312 | F34: 2222 | G34: 3630 | I34: Profitability
A35: Notes Payable | C35: 0 | D35: 0 | E35: 0 | F35: 0 | G35: 0 | I35: Operating Margin (EBIT/Sales) | J35: =C77/C68 -> 0.13568701 | K35: =D77/D68 -> 0.12710657 | L35: =E77/E68 -> 0.12684436 | M35: =F77/F68 -> 0.098771167 | N35: =G77/G68 -> 0.10240113
A36: Accrued Expenses | C36: 3108 | D36: 3075 | E36: 3133 | F36: 3125 | G36: 3184
A37: Taxes Payable | C37: 0 | D37: 0 | E37: 0 | F37: 0 | G37: 0 | I37: Net profit margin | J37: =C89/C68 -> 0.094191874 | K37: =D89/D68 -> 0.086869544 | L37: =E89/E68 -> 0.1024108 | M37: =F89/F68 -> 0.075109441 | N37: =G89/G68 -> 0.066850549
A38: Debt (Long-Term) Due In One Year | C38: 332 | D38: 419 | E38: 483 | F38: 958 | G38: 1414
A39: Other Current Liabilities | C39: 9777 | D39: 10276 | E39: 11009 | F39: 13115 | G39: 15107 | I39: Equity | J39: =C60 -> 10959 | K39: =D60 -> 9266 | L39: =E60 -> 6835 | M39: =F60 -> 6333 | N39: =G60 -> 6721
I40: Average Equity | K40: =(J39+K39)/2 -> 10112.5 | L40: =(K39+L39)/2 -> 8050.5 | M40: =(L39+M39)/2 -> 6584 | N40: =(M39+N39)/2 -> 6527
A41: Total Current Liabilities | C41: 13997 | D41: 15887 | E41: 16937 | F41: 19420 | G41: 23335
I42: ROE (based on prior ending) | K42: =D89/J39 -> 0.52304042 | L42: =E89/K39 -> 0.74681632 | M42: =F89/L39 -> 0.78068764 | N42: =G89/M39 -> 0.79219959
...

Sheet #4-5 Comparison
B3: #4
C6: P/E ratio
E8: 2021 | F8: 2022 | G8: 2023 | H8: 2024 | I8: 2025
D9: Netflix | E9: ='#2-3 NFLX'!J14 -> 53.620423 | F9: ='#2-3 NFLX'!K14 -> 29.625701 | G9: ='#2-3 NFLX'!L14 -> 40.468194 | H9: ='#2-3 NFLX'!M14 -> 44.942458 | I9: ='#2-3 NFLX'!N14 -> 37.088894
D10: Lockheed Martin | E10: ='#2-3 LMT'!J14 -> 15.251957 | F10: ='#2-3 LMT'!K14 -> 21.557652 | G10: ='#2-3 LMT'!L14 -> 15.719306 | H10: ='#2-3 LMT'!M14 -> 21.309963 | I10: ='#2-3 LMT'!N14 -> 22.077024
C20: Market Book
E22: 2021 | F22: 2022 | G22: 2023 | H22: 2024 | I22: 2025
D23: Netflix | E23: ='#2-3 NFLX'!J20 -> 17.308979 | F23: ='#2-3 NFLX'!K20 -> 6.4048624 | G23: ='#2-3 NFLX'!L20 -> 10.629894 | H23: ='#2-3 NFLX'!M20 -> 15.823188 | I23: ='#2-3 NFLX'!N20 -> 15.302391
D24: Lockheed Martin | E24: ='#2-3 LMT'!J20 -> 8.7887681 | F24: ='#2-3 LMT'!K20 -> 13.335685 | G24: ='#2-3 LMT'!L20 -> 15.914792 | H24: ='#2-3 LMT'!M20 -> 17.955149 | I24: ='#2-3 LMT'!N20 -> 16.479755
C33: Enterprise Value
B35: #5
E36: 2021 | F36: 2022 | G36: 2023 | H36: 2024 | I36: 2025
D37: Netflix | E37: ='#2-3 NFLX'!J28 -> 286423.07 | F37: ='#2-3 NFLX'!K28 -> 143949.51 | G37: ='#2-3 NFLX'!L28 -> 228685.61 | H37: ='#2-3 NFLX'!M28 -> 399930.88 | I37: ='#2-3 NFLX'!N28 -> 415188.7
D38: Lockheed Martin | E38: ='#2-3 LMT'!J28 -> 105814.11 | F38: ='#2-3 LMT'!K28 -> 137785.46 | G38: ='#2-3 LMT'!L28 -> 125971.6 | H38: ='#2-3 LMT'!M28 -> 132644.96 | I38: ='#2-3 LMT'!N28 -> 129410.43
E40: 2021 | F40: 2022 | G40: 2023 | H40: 2024 | I40: 2025
D41: Netflix | E41: =100*E37/$E37 -> 100 | F41: =100*F37/$E37 -> 50.25765 | G41: =100*G37/$E37 -> 79.841894 | H41: =100*H37/$E37 -> 139.62942 | I41: =100*I37/$E37 -> 144.95644
D42: Lockheed Martin | E42: =100*E38/$E38 -> 100 | F42: =100*F38/$E38 -> 130.21464 | G42: =100*G38/$E38 -> 119.04991 | H42: =100*H38/$E38 -> 125.35659 | I42: =100*I38/$E38 -> 122.29979

Sheet I-III
A2: Q1-2 | B2: FV=PV*(1+r)^n
A3: 7 points
B4: Beginning balance | C4: Time (yrs) | D4: rate | E4: Ending balance
A5: 1 | B5: 50000 | C5: 8 | D5: 0.12 | E5: =B5*(1+D5)^C5 -> 123798.16
A6: 2 | B6: =E5 -> 123798.16 | C6: 10 | D6: 0.08 | E6: =B6*(1+D6)^C6 -> 267270.94
A7: 3 | B7: =E6 -> 267270.94 | C7: 7 | D7: 0.06 | E7: =B7*(1+D7)^C7 -> 401876.67
B9: Beginning balance | C9: Time (yrs) | D9: rate | E9: Ending balance
A10: 1 | B10: 50000 | C10: 10 | D10: 0.11 | E10: =B10*(1+D10)^C10 -> 141971.05
A11: 2 | B11: =E10 -> 141971.05 | C11: 10 | D11: 0.07 | E11: =B11*(1+D11)^C11 -> 279278.54
A12: 3 | B12: =E11 -> 279278.54 | C12: 5 | D12: 0.04 | E12: =B12*(1+D12)^C12 -> 339785.05
A22: 10 points
A23: Q3. Calculate your monthly payment
B25: Price | E25: 20000
B26: Down payment | E26: =E25*F26 -> 3000 | F26: 0.15
B27: Loan balance | E27: =E25-E26 -> 17000
B29: PV | E29: =E27 -> 17000
B30: FV | E30: 0
B31: PMT | E31: =PMT(E32,E33,E29,E30) -> -348.78103
B32: Rate | E32: =F32/12 -> 0.0070833333 | F32: 0.085
B33: N | E33: =F33*12 -> 60 | F33: 5
A35: Q4 | B35: PV | E35: =PV(E38,E39,E37,E36) -> 7672.9921
B36: FV | E36: 0
B37: PMT | E37: =E31 -> -348.78103
B38: Rate | E38: =E32 -> 0.0070833333
B39: N | E39: 24
A41: 10 points
A43: Q4 | B43: House price | E43: 1100000
B44: Downpayment | E44: 0.1
B45: Loan | E45: =E43*(1-E44) -> 990000
B47: PV | E47: =-E45 -> -990000
B48: FV | E48: 0
B49: PMT | E49: =PMT(E50,E51,E47,E48) -> 6095.6003
B50: Rate | E50: =F50/12 -> 0.0052083333 | F50: 0.0625
B51: N | E51: 360
B53: Max mortgage pmt | E53: 0.36
B54: Monthly gross income required | E54: =E49/E53 -> 16932.223
B55: Annual income required | E55: =E54*12 -> 203186.68

Sheet IV
A17: 18 points
A18: Assumptions:
A19: Rate | D19: 0.07 | E19: Annual
A20: Retirement income | D20: 300000 | E20: Annual
A21: Time in retirement | D21: 20 | E21: years
A22: Initial savings | D22: 40000 | E22: per year
A23: Initial savings period | D23: 10 | E23: Years
A24: Cabint price | D24: 350000
A25: Working period before retirement | D25: 20 | E25: years
C28: Rate | D28: =D19 -> 0.07
A29: 1) | B29: Savings first 10 years | E29: PV today | I29: Using formulas | P29: Solution in
C30: PV | D30: 0 | P30: present value terms
C31: FV | D31: =FV(D33,D32,D34,D30) -> 552657.92 | E31: =D31/(1+D33)^10 -> 280943.26 | I31: Future value of annuity | P31: Retirement funds needed | R31: =-D43/(1+D28)^30 -> -417511.53
C32: N | D32: =D23 -> 10 | P32: Cabin funds needed | R32: =E37 -> -177922.25
C33: Rate | D33: =D28 -> 0.07 | P33: Savings in the first 10 years | R33: =E31 -> 280943.26
C34: PMT | D34: =-D22 -> -40000 | P34: Gap | R34: =SUM(R31:R33) -> -314490.52
B35: 10 year from today
J36: =D22*(((1+0.07)^10-1)/0.07) -> 552657.92 | P36: PV (gap in 10 yrs) | Q36: =R34*(1+Q39)^10 -> -618650.46
B37: Buy a cabin for | D37: -350000 | E37: =D37/(1+D33)^10 -> -177922.25 | F37: =D37*1.2 -> -420000 | G37: =D37*(1+D33)^20 -> -1354389.6 | J37: =-D24 -> -350000 | P37: FV
B38: Left over | D38: =D31+D37 -> 202657.92 | F38: =D31+F37 -> 132657.92 | J38: =SUM(J36:J37) -> 202657.92 | P38: N | Q38: 20
P39: Rate | Q39: =D28 -> 0.07
A40: 2) | B40: how much money (PV) needed to last 20 years to pay $300K per year | P40: PMT | Q40: =PMT(Q39,Q38,Q36,Q37) -> 58396.227
B41: In retirement 31 year from now: | K41: OR
P42: Using formula
C43: PV | D43: =PV(D46,D45,D47,D44) -> 3178204.3 | J43: =300000*((1-(1/(1+0.07)^20))/0.07) -> 3178204.3 | L43: =300000*(1/0.07-(1/(0.07*(1+0.07)^20))) -> 3178204.3
C44: FV | D44: 0
C45: N | D45: =D21 -> 20 | P45: PMT | Q45: =D19*Q36/(1-(1+D19)^(-D25)) -> -58396.227
C46: Rate | D46: =D19 -> 0.07
C47: PMT | D47: =-D20 -> -300000
A50: 3) | B50: Ian will have $202,657.92 at the end of year 10 (see 1. above) | I50: Future value of single investment | K50: FV= B(1+r)^n
B51: Annual savings needed between years 10 and 30
J52: =J38*(1+D28)^20 -> 784222.2 | K52: that's how much the $202,658 will grow to
C53: PV | D53: =-D38 -> -202657.92 | F53: =-F38 -> -132657.92 | G53: =-D31 -> -552657.92 | I53: Ian needs | J53: =J43 -> 3178204.3
C54: FV | D54: =D43 -> 3178204.3 | F54: =D43 -> 3178204.3 | G54: =F54 -> 3178204.3 | I54: So, he will be short | J54: =J53-J52 -> 2393982.1
C55: N | D55: =D25 -> 20 | F55: =D25 -> 20 | G55: =F55 -> 20 | I55: How much he needs to invest annualy to reach this goal:
C56: Rate | D56: =D19 -> 0.07 | F56: =D19 -> 0.07 | G56: =F56 -> 0.07 | I56: Formula: payment for known future value
C57: PMT | D57: =PMT(D56,D55,D53,D54) -> -58396.227 | E57: annual savings | F57: =PMT(F56,F55,F53,F54) -> -65003.732 | G57: =PMT(G56,G55,G53,G54) -> -25358.703
C59: PV | D59: 0 | F59: 0
C60: FV | D60: =FV(D62,D61,D63,D59) -> 2393982.1 | E60: ? | F60: =FV(F62,F61,F63,F59) -> 2664860
C61: N | D61: 20 | F61: 20
...

Sheet 1-2
B13: 2020 | C13: 198.2
B14: 2025 | C14: 245.5
B16: r | C16: =(C14/C13)^(1/5)-1 -> 0.043733371

Sheet 3
B1: Highlight your answers
B10: Cost of capital | C10: 0.1
B11: Time | C11: 0 | D11: 1 | E11: 2 | F11: 3
B12: Growth | E12: 0.03
B13: FCF | C13: 0 | D13: =C13*(1+D12) -> 0 | E13: 150
B14: Growing Perpetuity | D14: =E13/(C10-E12) -> 2142.8571
B15: Total FCF | D15: =SUM(D13:D14) -> 2142.8571
B16: PV | D16: =D15/(1+$C10)^D11 -> 1948.0519
B17: Total PV | C17: =SUM(D16:E16) -> 1948.0519
B19: PV=CF1/(r-g)

Sheet 4-6
F12: Face value | H12: 1000
F13: Coupon rate | H13: 0.08
B14: PV | C14: =-H12*H16 -> -1085 | F14: Annual payment | H14: =H12*H13 -> 80
B15: FV | C15: 1000 | F15: Quarterly payment | H15: =H14/4 -> 20
B16: PMT | C16: =H15 -> 20 | F16: Price | H16: 1.085
B17: Rate | C17: =RATE(C18,C16,C14,C15) -> 0.012335938
B18: N | C18: =D18*4 -> 12 | D18: 3
C20: =C17*4 -> 0.049343751 | D20: Annual (YTM)
B42: PV | C42: =PV(C45,C46,C44,C43) -> -1056.7609
B43: FV | C43: =H12 -> 1000
B44: PMT | C44: =H15 -> 20
B45: Rate | C45: =D45/4 -> 0.0125 | D45: 0.05
B46: N | C46: =D46*4 -> 8 | D46: 2

Sheet 7-8
B13: Nominal return
B14: Price purchased | C14: 700
B15: Price sold | C15: 1000
B16: Time | C16: 7
B18: r | C18: =(C15/C14)^(1/C16)-1 -> 0.052274028

Sheet 9
C21: 0.115
B23: Discount rate
B24: Time | D24: 0 | E24: 1 | F24: 2 | G24: 3
B25: Growth
B26: Sales (Revenue) | E26: 2000 | F26: 2100 | G26: 1900
B27: Cost of Goods Sold | C27: 0.6 | E27: =-E26*$C27 -> -1200 | F27: =-F26*$C27 -> -1260 | G27: =-G26*$C27 -> -1140
B28: Net Sales | E28: =SUM(E26:E27) -> 800 | F28: =SUM(F26:F27) -> 840 | G28: =SUM(G26:G27) -> 760
B29: Opportunity cost | E29: -80 | F29: -80 | G29: -80
B30: Required upgrade | F30: -100
B31: EBITDA | E31: =SUM(E28:E30) -> 720 | F31: =SUM(F28:F30) -> 660 | G31: =SUM(G28:G30) -> 680
B32: Depreciation | E32: =D42/5 -> -300 | F32: =E32 -> -300 | G32: =F32 -> -300 | I32: Salvage value calculations
B33: EBIT (operating income) | E33: =SUM(E31:E32) -> 420 | F33: =SUM(F31:F32) -> 360 | G33: =SUM(G31:G32) -> 380 | I33: Total investment | K33: =-D42 -> 1500
I34: Total depreciation | K34: =SUM(E32:G32) -> -900
I35: Book value | K35: =SUM(K33:K34) -> 600
B36: =B33 -> EBIT (operating income) | E36: =E33 -> 420 | F36: =F33 -> 360 | G36: =G33 -> 380 | I36: Sales price | K36: 450
B37: Tax | C37: 0.21 | E37: =-$C37*E36 -> -88.2 | F37: =-$C37*F36 -> -75.6 | G37: =-$C37*G36 -> -79.8 | I37: Loss on sale | K37: =K36-K35 -> -150
B38: EBIT(1-t) | E38: =SUM(E36:E37) -> 331.8 | F38: =SUM(F36:F37) -> 284.4 | G38: =SUM(G36:G37) -> 300.2 | I38: Tax (benefit) on loss | K38: =K37*C37 -> -31.5
B39: Depreciation | E39: =-E32 -> 300 | F39: =-F32 -> 300 | G39: =-G32 -> 300 | I39: Cash flow | K39: =K36-K38 -> 481.5
B40: Change in working capital | E40: =-E55 -> -400 | F40: =-F55 -> -20 | G40: =-G55 -> 40
B41: NWC recovery | G41: =G54 -> 380
B42: CapEx | D42: -1500
B43: Salvage value | G43: =K39 -> 481.5
A44: a) | B44: Free Cash Flow | D44: =SUM(D38:D43) -> -1500 | E44: =SUM(E38:E43) -> 231.8 | F44: =SUM(F38:F43) -> 564.4 | G44: =SUM(G38:G43) -> 1501.7
B46: Discounted free cash flow | D46: =D44/(1+$C21)^D24 -> -1500 | E46: =E44/(1+$C21)^E24 -> 207.89238 | F46: =F44/(1+$C21)^F24 -> 453.98057 | G46: =G44/(1+$C21)^G24 -> 1083.3245
A47: b) | B47: NPV | C47: =SUM(D46:G46) -> 245.19749
A48: c) | B48: IRR | C48: =IRR(D44:G44,0.1) -> 0.18500066
A49: d) | B49: Payback | C49: =F24+G52 -> 2.4686688
B51: Cumulative cash flow | D51: =D44 -> -1500 | E51: =D51+E44 -> -1268.2 | F51: =E51+F44 -> -703.8 | G51: =F51+G44 -> 797.9
G52: =-F51/G44 -> 0.46866884
B54: Net working capital | C54: 0.2 | E54: =$C54*E26 -> 400 | F54: =$C54*F26 -> 420 | G54: =$C54*G26 -> 380
B55: Change in NWC | D55: =D54-0 -> 0 | E55: =E54-D54 -> 400 | F55: =F54-E54 -> 20 | G55: =G54-F54 -> -40

Sheet 9 EC
C11: 0.115
B13: Discount rate
B14: Time | D14: 0 | E14: 1 | F14: 2 | G14: 3
B16: Sales (Revenue) | E16: 2000 | F16: 2100 | G16: 1900
B17: Cost of Goods Sold | C17: 0.6 | E17: =-E16*$C17 -> -1200 | F17: =-F16*$C17 -> -1260 | G17: =-G16*$C17 -> -1140
B18: Net Sales | E18: =SUM(E16:E17) -> 800 | F18: =SUM(F16:F17) -> 840 | G18: =SUM(G16:G17) -> 760
B19: Opportunity cost | E19: -80 | F19: -80 | G19: -80
B20: Required software upgrade | F20: -100
B21: Propulsion Upgrade | E21: -346.06987
B22: EBITDA | E22: =SUM(E18:E21) -> 373.93013 | F22: =SUM(F18:F21) -> 660 | G22: =SUM(G18:G21) -> 680
B23: Depreciation | E23: =D33/5 -> -300 | F23: =E23 -> -300 | G23: =F23 -> -300 | I23: Salvage value calculations
B24: EBIT (operating income) | E24: =SUM(E22:E23) -> 73.930132 | F24: =SUM(F22:F23) -> 360 | G24: =SUM(G22:G23) -> 380 | I24: Total investment | K24: =-D33 -> 1500
I25: Total depreciation | K25: =SUM(E23:G23) -> -900
I26: Book value | K26: =SUM(K24:K25) -> 600
B27: =B24 -> EBIT (operating income) | E27: =E24 -> 73.930132 | F27: =F24 -> 360 | G27: =G24 -> 380 | I27: Sales price | K27: 450
B28: Tax | C28: 0.21 | E28: =-$C28*E27 -> -15.525328 | F28: =-$C28*F27 -> -75.6 | G28: =-$C28*G27 -> -79.8 | I28: Loss on sale | K28: =K27-K26 -> -150
B29: EBIT(1-t) | E29: =SUM(E27:E28) -> 58.404804 | F29: =SUM(F27:F28) -> 284.4 | G29: =SUM(G27:G28) -> 300.2 | I29: Tax (benefit) on loss | K29: =K28*C28 -> -31.5
B30: Depreciation | E30: =-E23 -> 300 | F30: =-F23 -> 300 | G30: =-G23 -> 300 | I30: Cash flow | K30: =K27-K29 -> 481.5
B31: Change in working capital | E31: =-E46 -> -400 | F31: =-F46 -> -20 | G31: =-G46 -> 40
B32: NWC recovery | G32: =G45 -> 380
B33: CapEx | D33: -1500
B34: Salvage value | G34: =K30 -> 481.5
A35: a) | B35: Free Cash Flow | D35: =SUM(D29:D34) -> -1500 | E35: =SUM(E29:E34) -> -41.595196 | F35: =SUM(F29:F34) -> 564.4 | G35: =SUM(G29:G34) -> 1501.7
B37: Discounted free cash flow | D37: =D35/(1+$C11)^D14 -> -1500 | E37: =E35/(1+$C11)^E14 -> -37.305108 | F37: =F35/(1+$C11)^F14 -> 453.98057 | G37: =G35/(1+$C11)^G14 -> 1083.3245
A38: b) | B38: NPV | C38: =SUM(D37:G37) -> 0
A39: c) | B39: IRR | C39: =IRR(D35:G35,0.1) -> 0.115
A40: d) | B40: Payback | C40: =F14+G43 -> 2.650726
B42: Cumulative cash flow | D42: =D35 -> -1500 | E42: =D42+E35 -> -1541.5952 | F42: =E42+F35 -> -977.1952 | G42: =F42+G35 -> 524.5048
G43: =-F42/G35 -> 0.65072597
B45: Net working capital | C45: 0.2 | E45: =$C45*E16 -> 400 | F45: =$C45*F16 -> 420 | G45: =$C45*G16 -> 380
B46: Change in NWC | D46: =D45-0 -> 0 | E46: =E45-D45 -> 400 | F46: =F45-E45 -> 20 | G46: =G45-F45 -> -40

Sheet Project analysis 
A1: LMT
B2: Assumptions | D2: 0 | E2: 1 | F2: 2 | G2: 3 | H2: 4 | I2: 5 | P2: Sales | Q2: =B21 -> 97.818908 | AB2: To create NPV Profile graph from the Data Table
A3: Growth rate | F3: 0.03 | G3: 0.05 | H3: 0.07 | I3: 0.07 | P3: 0.005 | Q3: -713.40282 | AB3: 1. Connect Cell Q2 to Cell B19 (with NPV calculation)
A4: Revenue | B4: ='LMT fiinancials'!G68 -> 75048 | C4: 0.02 | E4: =B4*C4 -> 1500.96 | F4: =E4*(1+F3) -> 1545.9888 | G4: =F4*(1+G3) -> 1623.2882 | H4: =G4*(1+H3) -> 1736.9184 | I4: =H4*(1+I3) -> 1858.5027 | P4: 0.01 | Q4: -442.99558 | AB4: 2. Enter sale growth rates you would like to use in your sensitivity analysis (P3:P5) - from 2% to 4% (or any other set you desire)
P5: 0.015 | Q5: -172.58833 | AB5: 3. Highlight cells P2:Q5
A6: EBITDA | B6: ='LMT fiinancials'!G74 -> 9372 | C6: =B6/B4*2 -> 0.24976015 | E6: =$C6*E4 -> 374.88 | F6: =$C6*F4 -> 386.1264 | G6: =$C6*G4 -> 405.43272 | H6: =$C6*H4 -> 433.81301 | I6: =$C6*I4 -> 464.17992 | P6: 0.02 | Q6: 97.818908 | AB6: 4. Click on Data>>What If >> Data Table
A7: Opportunity cost | E7: -35 | F7: =E7 -> -35 | G7: =F7 -> -35 | H7: =G7 -> -35 | P7: 0.025 | Q7: 368.22615 | AB7: 5. Click on Column Input Cell and enter Cell C4 (revenue growth) >>OK
A8: System upgrade | E8: -120 | G8: 120 | P8: 0.03 | Q8: 638.63339 | AB8: 6. Data will be automatically populated in your table with NPVs
A9: Depreciation | E9: =-E30 -> -177.318 | F9: =-F30 -> -177.318 | G9: =-G30 -> -177.318 | H9: =-H30 -> -212.7816 | I9: =-I30 -> -212.7816
A10: EBIT | E10: =SUM(E6:E9) -> 42.562 | F10: =SUM(F6:F9) -> 173.8084 | G10: =SUM(G6:G9) -> 313.11472 | H10: =SUM(H6:H9) -> 186.03141 | I10: =SUM(I6:I9) -> 251.39832
A11: Tax | B11: =B49 -> 0.15281999 | E11: =-E10*$B11 -> -6.5043246 | F11: =-F10*$B11 -> -26.561399 | G11: =-G10*$B11 -> -47.850189 | H11: =-H10*$B11 -> -28.429319 | I11: =-I10*$B11 -> -38.41869 | AB11: 7. Create graph based on your table
A12: EBIT(1-T) | E12: =SUM(E10:E11) -> 36.057675 | F12: =SUM(F10:F11) -> 147.247 | G12: =SUM(G10:G11) -> 265.26453 | H12: =SUM(H10:H11) -> 157.60209 | I12: =SUM(I10:I11) -> 212.97963
A13: Depreciation | E13: =-E9 -> 177.318 | F13: =-F9 -> 177.318 | G13: =-G9 -> 177.318 | H13: =-H9 -> 212.7816 | I13: =-I9 -> 212.7816
A14: Change in NWC | E14: =-E34 -> -418.34 | F14: =-F34 -> -12.5502 | G14: =-G34 -> -21.54451 | H14: =-H34 -> -31.67043 | I14: =-I34 -> -33.88736
A15: CapEx | D15: =-D29 -> -886.59 | E15: =-E29 -> 0 | F15: =-F29 -> 0 | G15: =-G29 -> -177.318 | H15: =-H29 -> 0 | I15: =-I29 -> 0
A16: Salvage value (assets) | I16: =L31 -> 58.617642
A17: Recovery of NWC | I17: =I33 -> 517.9925
A18: Free Cash Flow to Firm | D18: =SUM(D12:D17) -> -886.59 | E18: =SUM(E12:E17) -> -204.96432 | F18: =SUM(F12:F17) -> 312.0148 | G18: =SUM(G12:G17) -> 243.72002 | H18: =SUM(H12:H17) -> 338.71326 | I18: =SUM(I12:I17) -> 968.48401
A19: Discount factor | D19: =1/(1+$B24)^D2 -> 1 | E19: =1/(1+$B24)^E2 -> 0.88888889 | F19: =1/(1+$B24)^F2 -> 0.79012346 | G19: =1/(1+$B24)^G2 -> 0.70233196 | H19: =1/(1+$B24)^H2 -> 0.62429508 | I19: =1/(1+$B24)^I2 -> 0.55492896
A20: PV of Free Cash Flows | D20: =D18*D19 -> -886.59 | E20: =E18*E19 -> -182.19051 | F20: =F18*F19 -> 246.53021 | G20: =G18*G19 -> 171.17236 | H20: =H18*H19 -> 211.45702 | I20: =I18*I19 -> 537.43982
A21: NPV | B21: =SUM(D20:I20) -> 97.818908
A22: IRR | B22: =IRR(D18:I18,0.1) -> 0.15190534
P23: Discount rate | Q23: =B21 -> 97.818908
A24: Discount rate (WACC) | B24: 0.125 | C24: calculated | P24: 0.095 | Q24: 222.8901
A25: Cumulative cash flows | D25: =D18 -> -886.59 | E25: =D25+E18 -> -1091.5543 | F25: =E25+F18 -> -779.53952 | G25: =F25+G18 -> -535.8195 | H25: =G25+H18 -> -197.10624 | I25: =H25+I18 -> 771.37777 | K25: Total investments | L25: =SUM(D29:I29) -> 1063.908 | P25: 0.105 | Q25: 179.14958
A26: Years | D26: 0 | E26: 1 | F26: 2 | G26: 3 | H26: =-G25/H18 -> 1.5819266 | K26: Accumulated depreciation | L26: =SUM(D30:I30) -> 957.5172 | P26: 0.115 | Q26: 137.49897
K27: End. book value | L27: =L25-L26 -> 106.3908 | P27: 0.125 | Q27: 97.818908
B28: 2025 Net PPE | G28: 0.2 | K28: Recovered | L28: 50 | P28: 0.135 | Q28: 59.997921
A29: Investments (CapEx) | B29: ='LMT fiinancials'!G23 -> 9851 | C29: 0.09 | D29: =B29*C29 -> 886.59 | G29: =G28*D29 -> 177.318 | K29: Gain (loss) | L29: =L28-L27 -> -56.3908 | P29: 0.145 | Q29: 23.931825
A30: Depreciation (adjusted for additional CapEx) | E30: =D29/5 -> 177.318 | F30: =E30+E29/5 -> 177.318 | G30: =F30+F29/5 -> 177.318 | H30: =G30+G29/5 -> 212.7816 | I30: =H30+H29/5 -> 212.7816 | K30: Tax benefit (payment) | L30: =-L29*B49 -> 8.6176417
K31: Total salvage cash flow | L31: =L28+L30 -> 58.617642
A33: NWC % Revenue | B33: =B43/B4 -> 0.27871496 | D33: 0 | E33: =$B33*E4 -> 418.34 | F33: =$B33*F4 -> 430.8902 | G33: =$B33*G4 -> 452.43471 | H33: =$B33*H4 -> 484.10514 | I33: =$B33*I4 -> 517.9925 | J33: Assume: NWC fully recovered at the end of the project
A34: Change in NWC | E34: =E33-D33 -> 418.34 | F34: =F33-E33 -> 12.5502 | G34: =G33-F33 -> 21.54451 | H34: =H33-G33 -> 31.67043 | I34: =I33-H33 -> 33.88736
A38: Working capital
A39: Cash | B39: ='LMT fiinancials'!G12 -> 4121
A40: A/R | B40: ='LMT fiinancials'!G13 -> 16902
A41: Inventory | B41: ='LMT fiinancials'!G14 -> 3524
A42: A/P | B42: ='LMT fiinancials'!G34 -> 3630
A43: NWC | B43: =B39+B40+B41-B42 -> 20917
A44: Change in NWC | Q44: Scenario Analysis
...

Sheet LMT fiinancials
A1: NAME: | C1: LOCKHEED MARTIN CORP
A2: TICKER SYMBOL: | C2: LMT
A3: PRIMARY SIC CODE: | C3: 3760
A4: STOCK EXCHANGE: | C4: 11 | D4: New York Stock Exchange
A5: CUSIP: | C5: 539830
A7: DATA in millions
A8: STATEMENT OF FINANCIAL POSITION
A9: Fiscal Year: | C9: 2021 | D9: 2022 | E9: 2023 | F9: 2024 | G9: 2025
A10: (FYR Ending): | C10: (31DEC2021 ) | D10: (31DEC2022 ) | E10: (31DEC2023 ) | F10: (31DEC2024 ) | G10: (31DEC2025 )
A11: ASSETS
A12: Cash & Equivalents | C12: 3604 | D12: 2547 | E12: 1442 | F12: 2483 | G12: 4121
A13: Receivables - Total (Net) | C13: 12542 | D13: 14823 | E13: 15315 | F13: 15308 | G13: 16902
A14: Inventories - Total | C14: 2981 | D14: 3088 | E14: 3132 | F14: 3474 | G14: 3524
A15: Prepaid Expenses | C15: 0 | D15: 0 | E15: 0 | F15: 0 | G15: 0
A16: Current Assets - Other | C16: 688 | D16: 533 | E16: 632 | F16: 584 | G16: 815
A18: Current Assets - Total | C18: 19815 | D18: 20991 | E18: 20521 | F18: 21849 | G18: 25362
A20: Plant, Property & Equip (Gross) | C20: 20400 | D20: 21238 | E20: 22282 | F20: 23219 | G20: 24079
A21: Accumulated Depreciation | C21: 11503 | D21: 12163 | E21: 12812 | F21: 13493 | G21: 14228
A23: Plant, Property & Equip (Net) | C23: 8897 | D23: 9075 | E23: 9470 | F23: 9726 | G23: 9851
A25: Investments at Equity | C25: 689 | D25: 685 | E25: 701 | F25: 654 | G25: 653
A26: Investments and Advances - Other
A27: Intangibles | C27: 14296 | D27: 14158 | E27: 14411 | F27: 14982 | G27: 15618
A28: Deferred Charges | E28: 0 | F28: 0 | G28: 0
A29: Assets - Other | C29: 7176 | D29: 7971 | E29: 7353 | F29: 8406 | G29: 8356
A31: TOTAL ASSETS | C31: 50873 | D31: 52880 | E31: 52456 | F31: 55617 | G31: 59840
A33: LIABILITIES
A34: Accounts Payable | C34: 780 | D34: 2117 | E34: 2312 | F34: 2222 | G34: 3630
A35: Notes Payable | C35: 0 | D35: 0 | E35: 0 | F35: 0 | G35: 0
A36: Accrued Expenses | C36: 3108 | D36: 3075 | E36: 3133 | F36: 3125 | G36: 3184
A37: Taxes Payable | C37: 0 | D37: 0 | E37: 0 | F37: 0 | G37: 0
A38: Debt (Long-Term) Due In One Year | C38: 332 | D38: 419 | E38: 483 | F38: 958 | G38: 1414
A39: Other Current Liabilities | C39: 9777 | D39: 10276 | E39: 11009 | F39: 13115 | G39: 15107
A41: Total Current Liabilities | C41: 13997 | D41: 15887 | E41: 16937 | F41: 19420 | G41: 23335
A43: Long Term Debt | C43: 12770 | D43: 16345 | E43: 18153 | F43: 20460 | G43: 21357
A44: Deferred Taxes (Balance Sheet) | C44: 8 | D44: 5 | E44: 10 | F44: 24 | G44: 18
A45: Investment Tax Credit | C45: 0 | D45: 0 | E45: 0 | F45: 0 | G45: 0
A46: Liabilities - Other | C46: 13139 | D46: 11377 | E46: 10521 | F46: 9380 | G46: 8409
A47: Noncontrolling Interest - Redeemable | C47: 0 | D47: 0 | E47: 0 | F47: 0 | G47: 0
A49: TOTAL LIABILITIES | C49: 39914 | D49: 43614 | E49: 45621 | F49: 49284 | G49: 53119
A51: SHAREHOLDERS' EQUITY
...

Sheet Returns by year
B2: Annual Returns on Investments in
A3: Year | B3: S&P 500 (includes dividends) | C3: US Small cap (bottom decile) | D3: 3-month T.Bill | E3: US T. Bond (10-year) | F3: Baa Corporate Bond | G3: Real Estate
A4: 1928 | B4: 0.43811155 | C4: 0.6215 | D4: 0.0308 | E4: 0.0083547086 | F4: 0.032195515 | G4: 0.014910537 | I4: =Table134[[#This Row],[S&P 500 (includes dividends)]]-Table134[[#This Row],[US T. Bond (10-year)]] -> 0.42975684
A5: 1929 | B5: -0.082979466 | C5: -0.4608 | D5: 0.0316 | E5: 0.042038042 | F5: 0.030178562 | G5: -0.020568071 | I5: =Table134[[#This Row],[S&P 500 (includes dividends)]]-Table134[[#This Row],[US T. Bond (10-year)]] -> -0.12501751
A6: 1930 | B6: -0.25123636 | C6: -0.4835 | D6: 0.0455 | E6: 0.045409314 | F6: 0.0053978095 | G6: -0.043 | I6: =Table134[[#This Row],[S&P 500 (includes dividends)]]-Table134[[#This Row],[US T. Bond (10-year)]] -> -0.29664568
A7: 1931 | B7: -0.43837549 | C7: -0.4362 | D7: 0.0231 | E7: -0.02558856 | F7: -0.15680775 | G7: -0.081504702 | I7: =Table134[[#This Row],[S&P 500 (includes dividends)]]-Table134[[#This Row],[US T. Bond (10-year)]] -> -0.41278693
A8: 1932 | B8: -0.086423645 | C8: 0.2865 | D8: 0.0107 | E8: 0.08790307 | F8: 0.23589602 | G8: -0.10466439 | I8: =Table134[[#This Row],[S&P 500 (includes dividends)]]-Table134[[#This Row],[US T. Bond (10-year)]] -> -0.17432672
A9: 1933 | B9: 0.49982225 | C9: 1.466 | D9: 0.0096 | E9: 0.018552721 | F9: 0.12966894 | G9: -0.038119441 | I9: =Table134[[#This Row],[S&P 500 (includes dividends)]]-Table134[[#This Row],[US T. Bond (10-year)]] -> 0.48126953
A10: 1934 | B10: -0.011885657 | C10: 0.2307 | D10: 0.0027833333 | E10: 0.079634426 | F10: 0.18816429 | G10: 0.029062087 | I10: =Table134[[#This Row],[S&P 500 (includes dividends)]]-Table134[[#This Row],[US T. Bond (10-year)]] -> -0.091520083
A11: 1935 | B11: 0.46740421 | C11: 0.549 | D11: 0.001675 | E11: 0.044720477 | F11: 0.13307732 | G11: 0.097658337 | I11: =Table134[[#This Row],[S&P 500 (includes dividends)]]-Table134[[#This Row],[US T. Bond (10-year)]] -> 0.42268373
A12: 1936 | B12: 0.3194341 | C12: 0.9641 | D12: 0.001725 | E12: 0.050178754 | F12: 0.11383816 | G12: 0.032186015 | I12: =Table134[[#This Row],[S&P 500 (includes dividends)]]-Table134[[#This Row],[US T. Bond (10-year)]] -> 0.26925535
A13: 1937 | B13: -0.35336729 | C13: -0.5394 | D13: 0.0027583333 | E13: 0.013791461 | F13: -0.044161917 | G13: 0.025633912 | I13: =Table134[[#This Row],[S&P 500 (includes dividends)]]-Table134[[#This Row],[US T. Bond (10-year)]] -> -0.36715875
A14: 1938 | B14: 0.29282654 | C14: 0.0516 | D14: 0.00065 | E14: 0.042132485 | F14: 0.092358817 | G14: -0.0087368136 | I14: =Table134[[#This Row],[S&P 500 (includes dividends)]]-Table134[[#This Row],[US T. Bond (10-year)]] -> 0.25069405
A15: 1939 | B15: -0.010975647 | C15: -0.0486 | D15: 0.00045833333 | E15: 0.044122614 | F15: 0.079831378 | G15: -0.013016072 | I15: =Table134[[#This Row],[S&P 500 (includes dividends)]]-Table134[[#This Row],[US T. Bond (10-year)]] -> -0.055098261
... A101: 2025 | B101: 0.17723658 | C101: 0.1653 | D101: 0.0421 | E101: 0.077954809 | F101: 0.069627321 | G101: 0.015757066 | I101: =Table134[[#This Row],[S&P 500 (includes dividends)]]-Table134[[#This Row],[US T. Bond (10-year)]] -> 0.099281774
I103: =AVERAGE(I77:I101) -> 0.066290473 | J103: 25 years
I104: =AVERAGE(I72:I101) -> 0.075670688 | J104: 30 years
I105: =AVERAGE(I62:I101) -> 0.069246619 | J105: 40 years
I106: =AVERAGE(I52:I101) -> 0.065639832 | J106: 50 years

Sheet Interest rates and WACC
B3: For large non-financial service firms
B4: If interest coverage ratio is
B5: > | C5: ≤ to | D5: Rating is | E5: Spread is
B6: 8.5 | C6: 100000 | D6: Aaa/AAA | E6: 0.004
B7: 6.5 | C7: 8.49 | D7: Aa2/AA | E7: 0.0055
B8: 5.5 | C8: 6.49 | D8: A1/A+ | E8: 0.007
B9: 4.25 | C9: 5.49 | D9: A2/A | E9: 0.0078
B10: 3 | C10: 4.24 | D10: A3/A- | E10: 0.0089
B11: 2.5 | C11: 2.99 | D11: Baa2/BBB | E11: 0.0111
B12: 2.25 | C12: 2.49 | D12: Ba1/BB+ | E12: 0.0138
B13: 2 | C13: 2.24 | D13: Ba2/BB | E13: 0.0184
B14: 1.75 | C14: 1.99 | D14: B1/B+ | E14: 0.0275
B15: 1.5 | C15: 1.74 | D15: B2/B | E15: 0.0321
B16: 1.25 | C16: 1.49 | D16: B3/B- | E16: 0.0509
B17: 0.8 | C17: 1.24 | D17: Caa/CCC | E17: 0.0885
... B20: -100 | C20: 0.19 | D20: D2/D | E20: 0.19
B22: Source: A. Damodaran (https://pages.stern.nyu.edu/~adamodar/)
B25: Debt
B26: ST | C26: ='LMT fiinancials'!G38 -> 1414
B27: LT | C27: ='LMT fiinancials'!G43 -> 21357 | H27: Beta | I27: Source
B28: Total Debt | C28: =SUM(C26:C27) -> 22771 | D28: =1-D32 -> 0.13327179 | G28: LMT | H28: 0.25 | I28: Yahoo finance
G29: Defence industry average | H29: 0.7 | I29: Industry data
B30: Share Price | C30: =HistoricalData_1777412484820!B61 -> 634.22 | G30: Robotics Pure-Play | H30: 1.3 | I30: Industry data
B31: Number of shares | C31: ='LMT fiinancials'!G105 -> 233.5
B32: MVE | C32: =C30*C31 -> 148090.37 | D32: =C32/C34 -> 0.86672821
B34: Total value | C34: =C32+C28 -> 170861.37
B36: Beta | C36: 1.3
B37: r(risk free) | C37: ='Risk free rates'!B11/100 -> 0.0381
B38: MRP | C38: ='Returns by year'!I104 -> 0.075670688
B39: r(equity) | C39: =C37+C36*C38 -> 0.13647189
B41: r(debt) | C41: =C37+E10 -> 0.047
B42: Tax rate | C42: ='LMT fiinancials'!G83/'LMT fiinancials'!G82 -> 0.15281999
B44: WACC | C44: =D32*C39+D28*C41*(1-C42) -> 0.12359059
B45: Rounded | C45: 0.125

Sheet Risk free rates
A1: WGS5YR
A2: lin | B2: Percent, Not Seasonally Adjusted
A3: w | B3: Weekly, Ending Friday
A4: 46031 | B4: 2026-01-09 to 2026-04-24
A5: Market Yield on U.S. Treasury Securities at 5-Year Constant Maturity, Quoted on an Investment Basis
A6: Board of Governors of the Federal Reserve System (US)
A7: date | B7: value
A8: 46031 | B8: 3.72
A9: 46038 | B9: 3.77
A10: 46045 | B10: 3.85
A11: 46052 | B11: 3.81
A12: 46059 | B12: 3.8
A13: 46066 | B13: 3.7
A14: 46073 | B14: 3.65
A15: 46080 | B15: 3.58
A16: 46087 | B16: 3.67
A17: 46094 | B17: 3.8
A18: 46101 | B18: 3.87
A19: 46108 | B19: 4.02
... A23: 46136 | B23: 3.91

Sheet HistoricalData_1777412484820
A1: Date | B1: Close/Last | C1: Volume | D1: Open | E1: High | F1: Low
A2: 46139 | B2: 513.35 | C2: 2111366 | D2: 514.05 | E2: 527.66 | F2: 511.91
A3: 46136 | B3: 513.45 | C3: 3089157 | D3: 525 | E3: 526.8 | F3: 503.6003
A4: 46135 | B4: 529.79 | C4: 3212539 | D4: 533.91 | E4: 538.81 | F4: 522.26
A5: 46134 | B5: 555.43 | C5: 2289028 | D5: 575.88 | E5: 576.07 | F5: 550.19
A6: 46133 | B6: 571.95 | C6: 1603536 | D6: 580.29 | E6: 580.975 | F6: 568.84
A7: 46132 | B7: 581.28 | C7: 1722026 | D7: 593.6 | E7: 598 | F7: 578.23
A8: 46129 | B8: 592.19 | C8: 1701585 | D8: 604.33 | E8: 609.3811 | F8: 588.41
A9: 46128 | B9: 607.49 | C9: 853841 | D9: 610.71 | E9: 613 | F9: 601.41
A10: 46127 | B10: 611.1 | C10: 879314 | D10: 611 | E10: 615.59 | F10: 607.34
A11: 46126 | B11: 611.58 | C11: 905708 | D11: 617 | E11: 617 | F11: 609.06
A12: 46125 | B12: 619.69 | C12: 678726 | D12: 617.87 | E12: 622.51 | F12: 615.01
A13: 46122 | B13: 613.72 | C13: 874037 | D13: 619.28 | E13: 621.7 | F13: 607.1598
... A125: 45958 | B125: 485.77 | C125: 1220554 | D125: 486.37 | E125: 489.4 | F125: 483.62

Sheet WACC
B2: Beta | C2: 1 | D2: Yahoo Finance | G2: For smaller and riskier firms
B3: r(risk free) | C3: =FRED!B24/100 -> 0.0438 | D3: FRED | G3: If interest coverage ratio is
B4: MRP | C4: 0.055 | D4: Given | G4: greater than | H4: ≤ to | I4: Rating is | J4: Spread is
B5: r(equity) | C5: =C3+C2*C4 -> 0.0988 | G5: -100000 | H5: 0.499999 | I5: D2/D | J5: 0.19
C6: Ba1 | D6: Based on IRC | G6: 0.5 | H6: 0.799999 | I6: C2/C | J6: 0.16
B7: r(debt) | C7: =C3+C9 -> 0.0576 | D7: =C3+J17 -> 0.0508 | G7: 0.8 | H7: 1.249999 | I7: Ca2/CC | J7: 0.1261
B8: ICR=EBIT/Interest exp | D8: ='Financial statements'!H77/'Financial statements'!H78 -> 9.3678161 | G8: 1.25 | H8: 1.499999 | I8: Caa/CCC | J8: 0.0885
B9: Spread over risk-free rate | C9: =J13 -> 0.0138 | D9: =J17 -> 0.007 | G9: 1.5 | H9: 1.999999 | I9: B3/B- | J9: 0.0509
G10: 2 | H10: 2.499999 | I10: B2/B | J10: 0.0321
B11: Debt | G11: 2.5 | H11: 2.999999 | I11: B1/B+ | J11: 0.0275
B12: ST | C12: ='Financial statements'!H35+'Financial statements'!H38 -> 84.8 | G12: 3 | H12: 3.499999 | I12: Ba2/BB | J12: 0.0184
B13: LT | C13: ='Financial statements'!H43 -> 1508.8 | G13: 3.5 | H13: 3.9999999 | I13: Ba1/BB+ | J13: 0.0138 | L13: Ba1 | M13: =C3+J13 -> 0.0576
C14: =SUM(C12:C13) -> 1593.6 | D14: =1-D18 -> 0.37952779 | G14: 4 | H14: 4.499999 | I14: Baa2/BBB | J14: 0.0111 | L14: BBB- | M14: =C3+N14 -> 0.05625 | N14: =J14+P14 -> 0.01245 | O14: =J13-J14 -> 0.0027 | P14: =O14/2 -> 0.00135
G15: 4.5 | H15: 5.999999 | I15: A3/A- | J15: 0.0089
B16: Price per share | C16: ='Share prices'!B5 -> 36.54 | G16: 6 | H16: 7.499999 | I16: A2/A | J16: 0.0078
B17: Number of shares | C17: ='Financial statements'!H106 -> 71.3 | G17: 7.5 | H17: 9.499999 | I17: A1/A+ | J17: 0.007
B18: MVE | C18: =C17*C16 -> 2605.302 | D18: =C18/C20 -> 0.62047221 | G18: 9.5 | H18: 12.499999 | I18: Aa2/AA | J18: 0.0055
G19: 12.5 | H19: 100000 | I19: Aaa/AAA | J19: 0.004
B20: Total capital | C20: =C18+C14 -> 4198.902
B22: Tax rate | C22: ='Financial statements'!P83 -> 0.21305295
B24: WACC | C24: =C5*D18+C7*D14*(1-C22) -> 0.078505947
B25: WACC | C25: 0.079 | D25: rounded

Sheet DCF
B1: WACC | C1: =WACC!C25 -> 0.079 | D1: calculated
B2: g | C2: 0.03 | D2: given
C3: 2025 | E3: 1 | F3: 2 | G3: 3 | H3: 4
B4: Sales | C4: ='Financial statements'!H68 -> 2839 | D4: ='Financial statements'!P68 -> 0.066719299 | E4: =C4*(1+D4) -> 3028.4161 | F4: =E4*(1+$D4) -> 3230.4699 | G4: =F4*(1+$D4) -> 3446.0046 | H4: =G4*(1+$D4) -> 3675.9196
B5: COGS | D5: ='Financial statements'!P69 -> 0.59691325 | E5: =$D5*E4 -> 1807.7017 | F5: =$D5*F4 -> 1928.3103 | G5: =$D5*G4 -> 2056.9658 | H5: =$D5*H4 -> 2194.2051
B6: Gross Profit | E6: =E4-E5 -> 1220.7144 | F6: =F4-F5 -> 1302.1596 | G6: =G4-G5 -> 1389.0388 | H6: =H4-H5 -> 1481.7145
B7: SG&A | D7: ='Financial statements'!P72 -> 0.29927846 | E7: =$D7*E4 -> 906.33972 | F7: =$D7*F4 -> 966.81007 | G7: =$D7*G4 -> 1031.315 | H7: =$D7*H4 -> 1100.1236
B8: EBITDA | E8: =E6-E7 -> 314.37467 | F8: =F6-F7 -> 335.34953 | G8: =G6-G7 -> 357.72381 | H8: =H6-H7 -> 381.59089
B9: Depreciation | D9: ='Financial statements'!P75 -> 0.038843226 | E9: =$D9*E4 -> 117.63345 | F9: =$D9*F4 -> 125.48187 | G9: =$D9*G4 -> 133.85394 | H9: =$D9*H4 -> 142.78458
B10: EBIT | E10: =E8-E9 -> 196.74122 | F10: =F8-F9 -> 209.86765 | G10: =G8-G9 -> 223.86988 | H10: =H8-H9 -> 238.80632
B11: Tax | D11: ='Financial statements'!P83 -> 0.21305295 | E11: =E10*$D11 -> 41.916297 | F11: =F10*$D11 -> 44.712923 | G11: =G10*$D11 -> 47.696138 | H11: =H10*$D11 -> 50.878391
B12: EBIT(1-t) | E12: =E10-E11 -> 154.82492 | F12: =F10-F11 -> 165.15473 | G12: =G10-G11 -> 176.17374 | H12: =H10-H11 -> 187.92793
B13: Depreciation | E13: =E9 -> 117.63345 | F13: =F9 -> 125.48187 | G13: =G9 -> 133.85394 | H13: =H9 -> 142.78458
B14: Change in NWC | E14: =(E26-'Financial statements'!O18) -> -9.7777652 | F14: =F26-E26 -> 8.0878626 | G14: =G26-F26 -> 8.6274791 | H14: =H26-G26 -> 9.2030984
B15: CapEx | D15: ='Financial statements'!P26 -> 0.038181484 | E15: =$D15*E4 -> 115.62942 | F15: =$D15*F4 -> 123.34413 | G15: =$D15*G4 -> 131.57357 | H15: =H13*1.2 -> 171.34149
B16: FCFF | E16: =E12+E13-E14-E15 -> 166.60672 | F16: =F12+F13-F14-F15 -> 159.20461 | G16: =G12+G13-G14-G15 -> 169.82663 | H16: =H12+H13-H14-H15 -> 150.16791
B17: TV | H17: =H16*(1+C2)/(C1-C2) -> 3156.5908
B18: PV FCFF | E18: =E16/(1+$C1)^E3 -> 154.40845 | F18: =F16/(1+$C1)^F3 -> 136.7454 | G18: =G16/(1+$C1)^G3 -> 135.18903 | H18: =(H16+H17)/(1+$C1)^H3 -> 2439.5893
B19: EV | C19: =SUM(E18:H18) -> 2865.9322
E20: Adjusted (Debt) | F20: Adjusted (number of shares)
B21: MVE | C21: =C19-L22+L23 -> 1488.0322 | E21: =C19-K22+K23 -> 2398.0322 | F21: =E21 -> 2398.0322 | K21: 2024 | L21: 2025
B22: Per share | C22: =C21/L24 -> 20.870017 | E22: =E21/L24 -> 33.632991 | F22: =F21/K24 -> 50.805768 | J22: Debt | K22: ='Financial statements'!G35+'Financial statements'!G38+'Financial statements'!G43 -> 496.8 | L22: ='Financial statements'!H35+'Financial statements'!H38+'Financial statements'!H43 -> 1593.6
B23: Market price | C23: =WACC!C16 -> 36.54 | E23: =C23 -> 36.54 | F23: =E23 -> 36.54 | J23: Cash | K23: ='Financial statements'!G12 -> 28.9 | L23: ='Financial statements'!H12 -> 215.7
B24: Over(under) | C24: =C22/C23-1 -> -0.42884463 | J24: Number of shares | K24: ='Financial statements'!G106 -> 47.2 | L24: ='Financial statements'!H106 -> 71.3
B26: NWC | D26: ='Financial statements'!P19 -> 0.040028263 | E26: =$D26*E4 -> 121.22223 | F26: =$D26*F4 -> 129.3101 | G26: =$D26*G4 -> 137.93758 | H26: =$D26*H4 -> 147.14067

Sheet Relative
A1: Company | B1: Entity | C1: Market Cap | D1: Total Debt | E1: Cash & Equivalents | F1: Revenue (TTM/LTM) | G1: EBITDA (TTM/LTM) | I1: EV | J1: Sales | K1: EBITDA
A2: MillerKnoll | B2: MLKN | C2: 1030 | D2: 1790 | E2: 175 | F2: 3800 | G2: 385 | I2: =C2+D2-E2 -> 2645 | J2: =I2/F2 -> 0.69605263 | K2: =I2/G2 -> 6.8701299
A3: La-Z-Boy | B3: LZB | C3: 1465 | D3: 568 | E3: 308 | F3: 2130 | G3: 187 | I3: =C3+D3-E3 -> 1725 | J3: =I3/F3 -> 0.80985915 | K3: =I3/G3 -> 9.2245989
A4: Flexsteel Industries | B4: FLXS | C4: 280 | D4: 0 | E4: 57 | F4: 458 | G4: 40 | I4: =C4+D4-E4 -> 223 | J4: =I4/F4 -> 0.48689956 | K4: =I4/G4 -> 5.575
A5: Hooker Furnishings | B5: HOFT | C5: 180 | D5: 70 | E5: 45 | F5: 430 | G5: n.m. | I5: =C5+D5-E5 -> 205 | J5: =I5/F5 -> 0.47674419
A7: Sources: (StockAnalysis) | I7: Average | J7: =AVERAGE(J2:J5) -> 0.61738888 | K7: =AVERAGE(K2:K4) -> 7.2232429
B10: Sales | C10: EBITDA
A11: HNI | B11: ='Financial statements'!H68 -> 2839 | C11: ='Financial statements'!H74 -> 351.6
A12: Industry | B12: =J7 -> 0.61738888 | C12: =K7 -> 7.2232429
A13: EV | B13: =B12*B11 -> 1752.767 | C13: =C12*C11 -> 2539.6922
A14: Debt | B14: =WACC!C14 -> 1593.6 | C14: =B14 -> 1593.6
A15: Cash | B15: ='Financial statements'!H12 -> 215.7 | C15: =B15 -> 215.7
A16: MVE | B16: =B13-B14+B15 -> 374.86704 | C16: =C13-C14+C15 -> 1161.7922
A17: # of shares | B17: ='Financial statements'!H106 -> 71.3 | C17: =B17 -> 71.3
A18: Per share | B18: =B16/B17 -> 5.2576023 | C18: =C16/C17 -> 16.294421

Sheet Financial statements
A1: NAME: | C1: HNI CORP
A2: TICKER SYMBOL: | C2: HNI
A3: PRIMARY SIC CODE: | C3: 2522
A4: STOCK EXCHANGE: | C4: 11 | D4: New York Stock Exchange
A5: CUSIP: | C5: 404251
A8: STATEMENT OF FINANCIAL POSITION
A9: Fiscal Year: | C9: 2020 | D9: 2021 | E9: 2022 | F9: 2023 | G9: 2024 | H9: 2025
A10: (FYR Ending): | C10: (31DEC2020 ) | D10: (31DEC2021 ) | E10: (31DEC2022 ) | F10: (31DEC2023 ) | G10: (31DEC2024 ) | H10: (31DEC2025 )
A11: ASSETS
A12: Cash & Equivalents | C12: 117.807 | D12: 53.662 | E12: 19.4 | F12: 34.5 | G12: 28.9 | H12: 215.7
A13: Receivables - Total (Net) | C13: 203.218 | D13: 238.613 | E13: 218.2 | F13: 246.6 | G13: 249.6 | H13: 573.1
A14: Inventories - Total | C14: 137.811 | D14: 181.591 | E14: 180.1 | F14: 196.6 | G14: 194.3 | H14: 475.3 | P14: Average
A15: Prepaid Expenses | K15: 2020 | L15: 2021 | M15: 2022 | N15: 2023 | O15: 2024
A16: Current Assets - Other | C16: 36.899 | D16: 49.628 | E16: 51.5 | F16: 58.2 | G16: 51.7 | H16: 147.8 | J16: CA | L16: =D18 -> 523.494 | M16: =E18 -> 469.2 | N16: =F18 -> 535.9 | O16: =G18 -> 524.5
J17: CL(less debt) | L17: =D41-D38 -> 477.663 | M17: =E41-E38 -> 369.8 | N17: =F41-F38 -> 425.9 | O17: =G41-G38 -> 393.5
A18: Current Assets - Total | C18: 495.735 | D18: 523.494 | E18: 469.2 | F18: 535.9 | G18: 524.5 | H18: 1411.9 | J18: NWC | L18: =L16-L17 -> 45.831 | M18: =M16-M17 -> 99.4 | N18: =N16-N17 -> 110 | O18: =O16-O17 -> 131
J19: NWC/Sales | L19: =L18/L67 -> 0.020980971 | M19: =M18/M67 -> 0.042086544 | N19: =N18/N67 -> 0.045193098 | O19: =O18/O67 -> 0.051852438 | P19: =AVERAGE(L19:O19) -> 0.040028263
A20: Plant, Property & Equip (Gross) | C20: 996.106 | D20: 1041.743 | E20: 1042.6 | F20: 1321.1 | G20: 1314.3 | H20: 2101
A21: Accumulated Depreciation | C21: 553.835 | D21: 581.909 | E21: 590.3 | F21: 638.5 | G21: 648.6 | H21: 678
A23: Plant, Property & Equip (Net) | C23: 442.271 | D23: 459.834 | E23: 452.3 | F23: 682.6 | G23: 665.7 | H23: 1423 | J23: Net PP&E | K23: =C23 -> 442.271 | L23: =D23 -> 459.834 | M23: =E23 -> 452.3 | N23: =F23 -> 682.6 | O23: =G23 -> 665.7
J24: Depreciation | L24: =D75 -> 83.146 | M24: =E75 -> 84.2 | N24: =F75 -> 94.9 | O24: =G75 -> 107.8
A25: Investments at Equity | C25: 0 | D25: 0 | E25: 0 | F25: 0 | G25: 0 | H25: 46.4 | J25: CapEx | L25: =L23-K23+L24 -> 100.709 | M25: =M23-L23+M24 -> 76.666 | N25: =N23-M23+N24 -> 325.2 | O25: =O23-N23+O24 -> 90.9
A26: Investments and Advances - Other | C26: 15.898 | D26: 32.611 | E26: 42.1 | F26: 40.4 | G26: 38.1 | H26: 48.9 | J26: CapEx/Sales | L26: =L25/L67 -> 0.046103567 | M26: =M25/M67 -> 0.032460835 | O26: =O25/O67 -> 0.035980051 | P26: =AVERAGE(L26:O26) -> 0.038181484
A27: Intangibles | C27: 458.896 | D27: 471.502 | E27: 439.8 | F27: 651.9 | G27: 624.3 | H27: 1702.6
A28: Deferred Charges | C28: 0.6 | D28: 0.1 | E28: 1.2 | F28: 0.9 | G28: 0.5 | H28: 0.5
A29: Assets - Other | C29: 4.632 | D29: 10.356 | E29: 9.9 | F29: 17.1 | G29: 22 | H29: 251.7
A31: TOTAL ASSETS | C31: 1418.032 | D31: 1497.897 | E31: 1414.5 | F31: 1928.8 | G31: 1875.1 | H31: 4885
A33: LIABILITIES
A34: Accounts Payable | C34: 190.527 | D34: 233.759 | E34: 165.3 | F34: 193.7 | G34: 190.4 | H34: 380.4
A35: Notes Payable | C35: 0 | D35: 0 | E35: 0 | F35: 0 | G35: 0 | H35: 0
A36: Accrued Expenses | C36: 148.94 | D36: 181.278 | E36: 143.8 | F36: 157.9 | G36: 133.3 | H36: 533.1
A37: Taxes Payable | C37: 0 | D37: 0 | E37: 0 | F37: 0 | G37: 0 | H37: 0
A38: Debt (Long-Term) Due In One Year | C38: 22.4 | D38: 28.785 | E38: 25.3 | F38: 37.8 | G38: 84 | H38: 84.8
A39: Other Current Liabilities | C39: 77.161 | D39: 62.626 | E39: 60.7 | F39: 74.3 | G39: 69.8 | H39: 141
A41: Total Current Liabilities | C41: 439.028 | D41: 506.448 | E41: 395.1 | F41: 463.7 | G41: 477.5 | H41: 1139.3
A43: Long Term Debt | C43: 232.289 | D43: 245.738 | E43: 275.4 | F43: 540.2 | G43: 412.8 | H43: 1508.8
A44: Deferred Taxes (Balance Sheet) | C44: 74.706 | D44: 75.008 | E44: 61 | F44: 85.1 | G44: 71.6 | H44: 180.9
A45: Investment Tax Credit | C45: 0 | D45: 0 | E45: 0 | F45: 0 | G45: 0 | H45: 0
A46: Liabilities - Other | C46: 81.264 | D46: 80.736 | E46: 66.2 | F46: 78 | G46: 72.8 | H46: 220.4
A47: Noncontrolling Interest - Redeemable | C47: 0 | D47: 0 | E47: 0 | F47: 0 | G47: 0 | H47: 0
...

Sheet Credit rating

Sheet HNI share prices 1 year
E34: The SCS (Steelcase Inc.) acquisition by HNI was announced on August 4, 2025

Sheet MacroTrends_Data_Download_SCS
A1: MacroTrends Data Download
A2: SCS - Historical Price and Volume Data
A3: Note: Historical prices are adjusted for stock splits.
A5: Disclaimer and Terms of Use: Historical stock data is provided 'as is' and solely for informational purposes, not for trading purposes or advice.
A6: MacroTrends LLC expressly disclaims the accuracy, adequacy, or completeness of any data and shall not be liable for any errors, omissions or other defects in,
A7: delays or interruptions in such data, or for any actions taken in reliance thereon. Neither MacroTrends LLC nor any of our information providers will be liable
A8: for any damages relating to your use of the data provided.
A11: ATTRIBUTION: Proper attribution requires clear indication of the data source as "www.macrotrends.net".
A12: A "dofollow" backlink to the originating page is also required if the data is displayed on a web page.
A15: date | B15: open | C15: high | D15: low | E15: close | F15: volume
A16: 35844 | B16: 12.3575 | C16: 12.706 | D16: 12.2646 | E16: 12.4969 | F16: 15209982
A17: 35845 | B17: 12.8221 | C17: 13.0544 | D17: 12.4969 | E17: 13.0079 | F17: 2557167
A18: 35846 | B18: 13.0078 | C18: 13.1008 | D18: 12.5433 | E18: 12.7291 | F18: 1140602
A19: 35849 | B19: 12.6362 | C19: 12.6826 | D19: 12.311 | E19: 12.4039 | F19: 1360248
A20: 35850 | B20: 12.4039 | C20: 12.4736 | D20: 12.311 | E20: 12.4039 | F20: 668231
A21: 35851 | B21: 12.404 | C21: 12.7292 | D21: 12.3808 | E21: 12.6595 | F21: 593347
A22: 35852 | B22: 12.7524 | C22: 13.0079 | D22: 12.6362 | E22: 13.0079 | F22: 621592
A23: 35853 | B23: 13.0079 | C23: 13.4725 | D23: 13.0079 | E23: 13.4725 | F23: 483709
A24: 35856 | B24: 13.5189 | C24: 13.7048 | D24: 13.426 | E24: 13.6583 | F24: 344524
A25: 35857 | B25: 13.7512 | C25: 13.7512 | D25: 13.4028 | E25: 13.426 | F25: 460665
A26: 35858 | B26: 13.3796 | C26: 13.3796 | D26: 13.0079 | E26: 13.0776 | F26: 724541
A27: 35859 | B27: 13.0079 | C27: 13.0079 | D27: 12.822 | E27: 12.9614 | F27: 495599
... A6772: 45649 | B6772: 11.3543 | C6772: 11.4608 | D6772: 11.1027 | E6772: 11.2769 | F6772: 778638
A6773: 45650 | B6773: 11.2285 | C6773: 11.393 | D6773: 11.151 | E6773: 11.3543 | F6773: 381961 | U6773: Item | V6773: Value
A6774: 45652 | B6774: 11.2963 | C6774: 11.5479 | D6774: 11.2866 | E6774: 11.5189 | F6774: 503250 | U6774: Announcement date | V6774: 45873
A6775: 45653 | B6775: 11.4124 | C6775: 11.6544 | D6775: 11.4027 | E6775: 11.5866 | F6775: 743594 | U6775: Cash per SCS share | V6775: 7.2
A6776: 45656 | B6776: 11.5281 | C6776: 11.5574 | D6776: 11.284 | E6776: 11.4207 | F6776: 562250 | U6776: Stock per SCS share | V6776: 0.2192 HNI shares
A6777: 45657 | B6777: 11.4695 | C6777: 11.6061 | D6777: 11.4207 | E6777: 11.5378 | F6777: 657811 | U6777: Implied price per share | V6777: 18.3
A6778: 45659 | B6778: 11.6159 | C6778: 11.733 | D6778: 11.3621 | E6778: 11.3816 | F6778: 449798 | U6778: Total deal value | V6778: ≈ $2.2B
A6779: 45660 | B6779: 11.4695 | C6779: 11.4695 | D6779: 11.1669 | E6779: 11.3328 | F6779: 780509
A6780: 45663 | B6780: 11.3524 | C6780: 11.5476 | D6780: 11.1669 | E6780: 11.1669 | F6780: 819362 | V6780: =V6777-V6775 -> 11.1
A6781: 45664 | B6781: 11.2157 | C6781: 11.2938 | D6781: 10.835 | E6781: 10.9326 | F6781: 619547 | V6781: =V6780/0.2192 -> 50.638686
A6782: 45665 | B6782: 10.8057 | C6782: 11.0302 | D6782: 10.7374 | E6782: 11.0302 | F6782: 603342
A6783: 45667 | B6783: 10.835 | C6783: 10.9131 | D6783: 10.6691 | E6783: 10.7081 | F6783: 498605
A6784: 45670 | B6784: 10.6398 | C6784: 10.8741 | D6784: 10.6398 | E6784: 10.8643 | F6784: 501046 | U6784: Component | V6784: Detail
A6785: 45671 | B6785: 10.9131 | C6785: 11.0693 | D6785: 10.8741 | E6785: 10.9717 | F6785: 441504 | U6785: Cash per SCS share | V6785: 7.2
A6786: 45672 | B6786: 11.3035 | C6786: 11.3914 | D6786: 11.079 | E6786: 11.3328 | F6786: 583136 | U6786: Total cash needed | V6786: ~$0.9B (approx.)
A6787: 45673 | B6787: 11.284 | C6787: 11.3816 | D6787: 11.2059 | E6787: 11.284 | F6787: 413096 | U6787: Financing source | V6787: $1.1B 364‑day Senior Unsecured Bridge Facility
A6788: 45674 | B6788: 11.4402 | C6788: 11.4988 | D6788: 11.3426 | E6788: 11.4207 | F6788: 542825 | U6788: Lenders | V6788: J.P. Morgan & Wells Fargo
A6789: 45678 | B6789: 11.4988 | C6789: 11.5964 | D6789: 11.4207 | E6789: 11.5183 | F6789: 388987 | U6789: Purpose | V6789: Fund the cash portion of the merger consideration
...

Sheet FRED
A1: WGS10YR
A2: lin | B2: Percent, Not Seasonally Adjusted
A3: w | B3: Weekly, Ending Friday
A4: 46031 | B4: 2026-01-09 to 2026-05-08
A5: Market Yield on U.S. Treasury Securities at 10-Year Constant Maturity, Quoted on an Investment Basis
A6: Board of Governors of the Federal Reserve System (US)
A7: date | B7: value
A8: 46031 | B8: 4.17
A9: 46038 | B9: 4.19
A10: 46045 | B10: 4.27
A11: 46052 | B11: 4.24
A12: 46059 | B12: 4.26
A13: 46066 | B13: 4.14
A14: 46073 | B14: 4.08
A15: 46080 | B15: 4.02
A16: 46087 | B16: 4.1
A17: 46094 | B17: 4.21
A18: 46101 | B18: 4.27
A19: 46108 | B19: 4.38
... A25: 46150 | B25: 4.41

Sheet Share prices
A1: Date | B1: Close
A2: 46023 | B2: 47.79
A3: 46054 | B3: 44.96
A4: 46082 | B4: 33.39
A5: 46113 | B5: 36.54
A6: 46143 | B6: 30.7
